<?xml version="1.0" ?>
<!-- =================================================================================== -->
<!-- |    This document was autogenerated by xacro from /home/enrique/catkin_ws/src/algorithm/models/robot/robot.xacro | -->
<!-- |    EDITING THIS FILE BY HAND IS NOT RECOMMENDED                                 | -->
<!-- =================================================================================== -->
<robot name="robot">
  <!-- =================================================================================== -->
  <!-- |    This XACRO contains the integration of the different part of the robot       | -->
  <!-- =================================================================================== -->
  <!-- =================================================================================== -->
  <!-- |    This XACRO contains physical elements (the chassis and wheels ) of the robot | -->
  <!-- =================================================================================== -->
  <!-- The inertial calculations was taken from https://en.wikipedia.org/wiki/List_of_moments_of_inertia -->
  <!--BASE LINK-->
  <link name="base_link">

    </link>
  <!--CHASSIS LINK-->
  <joint name="chassis_joint" type="fixed">
    <parent link="base_link"/>
    <child link="chassis"/>
    <!--Origin of the joint-->
    <origin xyz="-0.1 0 0"/>
  </joint>
  <link name="chassis">
    <visual>
      <!-- Origin of the box -->
      <origin xyz="0.15 0 0.075"/>
      <geometry>
        <!--Geometry of the chassis (0.3(x dimension in meters), 0.3(y dimension in meters), 0.15 (z dimension in meters))-->
        <box size="0.3 0.3 0.15"/>
      </geometry>
      <material name="blue">
        <!-- The colors are RGB plus alpha (transparency) -->
        <color rgba="0 0 1 0.5"/>
      </material>
    </visual>
    <collision>
      <!-- Origin of the box -->
      <origin xyz="0.15 0 0.075"/>
      <geometry>
        <!--Geometry of the chassis (0.3(x dimension in meters), 0.3(y dimension in meters), 0.15 (z dimension in meters))-->
        <box size="0.3 0.3 0.15"/>
      </geometry>
    </collision>
    <inertial>
      <origin rpy="0 0 0" xyz="0.15 0 0.075"/>
      <mass value="0.5"/>
      <inertia ixx="0.004687499999999999" ixy="0.0" ixz="0.0" iyy="0.004687499999999999" iyz="0.0" izz="0.0075"/>
    </inertial>
  </link>
  <!-- LEFT WHEEL JOINT-->
  <joint name="left_wheel_joint" type="continuous">
    <parent link="base_link"/>
    <child link="left_wheel"/>
    <origin rpy="-1.5707963267948966 0 0" xyz="0 0.175 0"/>
    <axis xyz="0 0 1"/>
  </joint>
  <link name="left_wheel">
    <visual>
      <geometry>
        <cylinder length="0.04" radius="0.05"/>
      </geometry>
      <material name="blue">
        <!-- The colors are RGB plus alpha (transparency) -->
        <color rgba="0 0 1 0.5"/>
      </material>
    </visual>
    <collision>
      <geometry>
        <cylinder length="0.04" radius="0.05"/>
      </geometry>
    </collision>
    <inertial>
      <origin rpy="0 0 0" xyz="0 0 0"/>
      <mass value="0.1"/>
      <inertia ixx="7.583333333333335e-05" ixy="0.0" ixz="0.0" iyy="7.583333333333335e-05" iyz="0.0" izz="0.00012500000000000003"/>
    </inertial>
  </link>
  <!-- RIGHT WHEEL JOINT-->
  <joint name="right_wheel_joint" type="continuous">
    <parent link="base_link"/>
    <child link="right_wheel"/>
    <origin rpy="1.5707963267948966 0 0" xyz="0 -0.175 0"/>
    <axis xyz="0 0 -1"/>
  </joint>
  <link name="right_wheel">
    <visual>
      <geometry>
        <cylinder length="0.04" radius="0.05"/>
      </geometry>
      <material name="blue">
        <!-- The colors are RGB plus alpha (transparency) -->
        <color rgba="0 0 1 0.5"/>
      </material>
    </visual>
    <collision>
      <geometry>
        <cylinder length="0.04" radius="0.05"/>
      </geometry>
    </collision>
    <inertial>
      <origin rpy="0 0 0" xyz="0 0 0"/>
      <mass value="0.1"/>
      <inertia ixx="7.583333333333335e-05" ixy="0.0" ixz="0.0" iyy="7.583333333333335e-05" iyz="0.0" izz="0.00012500000000000003"/>
    </inertial>
  </link>
  <!-- CASTER WHEEL LINK -->
  <joint name="caster_wheel_joint" type="fixed">
    <parent link="chassis"/>
    <child link="caster_wheel"/>
    <origin xyz="0.24 0 0"/>
  </joint>
  <link name="caster_wheel">
    <visual>
      <geometry>
        <sphere radius="0.05"/>
      </geometry>
      <material name="black">
        <!-- The colors are RGB plus alpha (transparency) -->
        <color rgba="0 0 0 1.0"/>
      </material>
    </visual>
    <collision>
      <geometry>
        <sphere radius="0.05"/>
      </geometry>
    </collision>
    <inertial>
      <origin rpy="0 0 0" xyz="0 0 0"/>
      <mass value="0.1"/>
      <inertia ixx="0.00010000000000000005" ixy="0.0" ixz="0.0" iyy="0.00010000000000000005" iyz="0.0" izz="0.00010000000000000005"/>
    </inertial>
  </link>
</robot>

